127.0.0.1 - - [15/Mar/2023 15:57:22] "GET / HTTP/1.1" 200 -
----------------------------------------
Exception occurred during processing of request from ('127.0.0.1', 53574)
Traceback (most recent call last):
  File "/usr/lib/python3.9/socketserver.py", line 316, in _handle_request_noblock
    self.process_request(request, client_address)
  File "/usr/lib/python3.9/socketserver.py", line 347, in process_request
    self.finish_request(request, client_address)
  File "/usr/lib/python3.9/socketserver.py", line 360, in finish_request
    self.RequestHandlerClass(request, client_address, self)
  File "/usr/lib/python3.9/socketserver.py", line 747, in __init__
    self.handle()
  File "/usr/lib/python3.9/http/server.py", line 433, in handle
    self.handle_one_request()
  File "/usr/lib/python3.9/http/server.py", line 421, in handle_one_request
    method()
  File "/home/simon/Cosillas/entrees/pyentrees/srv/src/server.py", line 57, in do_POST
    additional_handler(e)
  File "/home/simon/Cosillas/entrees/pyentrees/srv/src/additional_logic.py", line 10, in additional_handler
    insert(e)
  File "/home/simon/Cosillas/entrees/pyentrees/srv/src/database.py", line 20, in insert
    conexion.execute("""INSERT INTO entrees(texto, tipo, timestamp) VALUES (?, ?, ?)""",
sqlite3.OperationalError: no such table: entrees
----------------------------------------
Killed
127.0.0.1 - - [15/Mar/2023 16:12:23] "POST / HTTP/1.1" 200 -
